<?xml version="1.0" ?>
<!-- =================================================================================== -->
<!-- |    This document was autogenerated by xacro from Spot_Arm_Export.xacro          | -->
<!-- |    EDITING THIS FILE BY HAND IS NOT RECOMMENDED                                 | -->
<!-- =================================================================================== -->
<robot name="Spot_Arm_Export" xmlns:xacro="http://www.ros.org/wiki/xacro">
  <material name="yellow">
    <color rgba="0.992 0.8705 0.08235 1.000"/>
  </material>
  <material name="black">
    <color rgba="0.254 0.254 0.235 1.000"/>
  </material>
  <material name="silver">
    <color rgba="0.4627 0.4627 0.4549 1.000"/>
  </material>
  <transmission name="Rev7_tran">
    <type>transmission_interface/SimpleTransmission</type>
    <joint name="Rev7">
      <hardwareInterface>hardware_interface/EffortJointInterface</hardwareInterface>
    </joint>
    <actuator name="Rev7_actr">
      <hardwareInterface>hardware_interface/EffortJointInterface</hardwareInterface>
      <mechanicalReduction>1</mechanicalReduction>
    </actuator>
  </transmission>
  <transmission name="Rev8_tran">
    <type>transmission_interface/SimpleTransmission</type>
    <joint name="Rev8">
      <hardwareInterface>hardware_interface/EffortJointInterface</hardwareInterface>
    </joint>
    <actuator name="Rev8_actr">
      <hardwareInterface>hardware_interface/EffortJointInterface</hardwareInterface>
      <mechanicalReduction>1</mechanicalReduction>
    </actuator>
  </transmission>
  <transmission name="Rev9_tran">
    <type>transmission_interface/SimpleTransmission</type>
    <joint name="Rev9">
      <hardwareInterface>hardware_interface/EffortJointInterface</hardwareInterface>
    </joint>
    <actuator name="Rev9_actr">
      <hardwareInterface>hardware_interface/EffortJointInterface</hardwareInterface>
      <mechanicalReduction>1</mechanicalReduction>
    </actuator>
  </transmission>
  <transmission name="Rev10_tran">
    <type>transmission_interface/SimpleTransmission</type>
    <joint name="Rev10">
      <hardwareInterface>hardware_interface/EffortJointInterface</hardwareInterface>
    </joint>
    <actuator name="Rev10_actr">
      <hardwareInterface>hardware_interface/EffortJointInterface</hardwareInterface>
      <mechanicalReduction>1</mechanicalReduction>
    </actuator>
  </transmission>
  <transmission name="Slider11_tran">
    <type>transmission_interface/SimpleTransmission</type>
    <joint name="Slider11">
      <hardwareInterface>hardware_interface/EffortJointInterface</hardwareInterface>
    </joint>
    <actuator name="Slider11_actr">
      <hardwareInterface>hardware_interface/EffortJointInterface</hardwareInterface>
      <mechanicalReduction>1</mechanicalReduction>
    </actuator>
  </transmission>
  <transmission name="Rev14_tran">
    <type>transmission_interface/SimpleTransmission</type>
    <joint name="Rev14">
      <hardwareInterface>hardware_interface/EffortJointInterface</hardwareInterface>
    </joint>
    <actuator name="Rev14_actr">
      <hardwareInterface>hardware_interface/EffortJointInterface</hardwareInterface>
      <mechanicalReduction>1</mechanicalReduction>
    </actuator>
  </transmission>
  <transmission name="Rev15_tran">
    <type>transmission_interface/SimpleTransmission</type>
    <joint name="Rev15">
      <hardwareInterface>hardware_interface/EffortJointInterface</hardwareInterface>
    </joint>
    <actuator name="Rev15_actr">
      <hardwareInterface>hardware_interface/EffortJointInterface</hardwareInterface>
      <mechanicalReduction>1</mechanicalReduction>
    </actuator>
  </transmission>
  <gazebo>
    <plugin filename="libgazebo_ros_control.so" name="control"/>
  </gazebo>
  <gazebo reference="base_link">
    <material>Gazebo/Silver</material>
    <mu1>0.2</mu1>
    <mu2>0.2</mu2>
    <selfCollide>true</selfCollide>
    <gravity>true</gravity>
  </gazebo>
  <gazebo reference="link1_1">
    <material>Gazebo/Silver</material>
    <mu1>0.2</mu1>
    <mu2>0.2</mu2>
    <selfCollide>true</selfCollide>
  </gazebo>
  <gazebo reference="link2__1">
    <material>Gazebo/Silver</material>
    <mu1>0.2</mu1>
    <mu2>0.2</mu2>
    <selfCollide>true</selfCollide>
  </gazebo>
  <gazebo reference="link3_1">
    <material>Gazebo/Silver</material>
    <mu1>0.2</mu1>
    <mu2>0.2</mu2>
    <selfCollide>true</selfCollide>
  </gazebo>
  <gazebo reference="link4_1">
    <material>Gazebo/Silver</material>
    <mu1>0.2</mu1>
    <mu2>0.2</mu2>
    <selfCollide>true</selfCollide>
  </gazebo>
  <gazebo reference="link5_1">
    <material>Gazebo/Silver</material>
    <mu1>0.2</mu1>
    <mu2>0.2</mu2>
    <selfCollide>true</selfCollide>
  </gazebo>
  <gazebo reference="link6_1">
    <material>Gazebo/Silver</material>
    <mu1>0.2</mu1>
    <mu2>0.2</mu2>
    <selfCollide>true</selfCollide>
  </gazebo>
  <gazebo reference="link7_1">
    <material>Gazebo/Silver</material>
    <mu1>0.2</mu1>
    <mu2>0.2</mu2>
    <selfCollide>true</selfCollide>
  </gazebo>
  <link name="base_link">
    <inertial>
      <origin rpy="0 0 0" xyz="1.4893738513430887e-17 1.4893738513430887e-17 0.018976000606365378"/>
      <mass value="1.6720303943376955"/>
      <inertia ixx="0.002269" ixy="0.0" ixz="-0.0" iyy="0.002269" iyz="-0.0" izz="0.004095"/>
    </inertial>
    <visual>
      <origin rpy="0 0 0" xyz="0 0 0"/>
      <geometry>
        <mesh filename="package://Spot_Arm_Export_description/meshes/base_link.stl" scale="0.001 0.001 0.001"/>
      </geometry>
      <material name="black"/>
    </visual>
    <collision>
      <origin rpy="0 0 0" xyz="0 0 0"/>
      <geometry>
        <mesh filename="package://Spot_Arm_Export_description/meshes/base_link.stl" scale="0.001 0.001 0.001"/>
      </geometry>
    </collision>
  </link>
  <link name="link1_1">
    <inertial>
      <origin rpy="0 0 0" xyz="-0.00010166140320390767 -0.002439812837878551 0.06408235101807577"/>
      <mass value="1.323325671789871"/>
      <inertia ixx="0.005142" ixy="-0.0" ixz="5e-06" iyy="0.003539" iyz="0.000116" izz="0.003127"/>
    </inertial>
    <visual>
      <origin rpy="0 0 0" xyz="-0.0 -0.0 -0.04"/>
      <geometry>
        <mesh filename="package://Spot_Arm_Export_description/meshes/link1_1.stl" scale="0.001 0.001 0.001"/>
      </geometry>
      <material name="black"/>
    </visual>
    <collision>
      <origin rpy="0 0 0" xyz="-0.0 -0.0 -0.04"/>
      <geometry>
        <mesh filename="package://Spot_Arm_Export_description/meshes/link1_1.stl" scale="0.001 0.001 0.001"/>
      </geometry>
    </collision>
  </link>
  <link name="link2__1">
    <inertial>
      <origin rpy="0 0 0" xyz="0.16558407457674612 -0.03000000000000001 2.9449114878343785e-06"/>
      <mass value="4.994414599306621"/>
      <inertia ixx="0.004693" ixy="-0.0" ixz="-2e-06" iyy="0.041317" iyz="-0.0" izz="0.041288"/>
    </inertial>
    <visual>
      <origin rpy="0 0 0" xyz="-0.0 -0.03 -0.14"/>
      <geometry>
        <mesh filename="package://Spot_Arm_Export_description/meshes/link2__1.stl" scale="0.001 0.001 0.001"/>
      </geometry>
      <material name="yellow"/>
    </visual>
    <collision>
      <origin rpy="0 0 0" xyz="-0.0 -0.03 -0.14"/>
      <geometry>
        <mesh filename="package://Spot_Arm_Export_description/meshes/link2__1.stl" scale="0.001 0.001 0.001"/>
      </geometry>
    </collision>
  </link>
  <link name="link3_1">
    <inertial>
      <origin rpy="0 0 0" xyz="0.07808838335862711 -0.010000000424296312 0.07857423931894233"/>
      <mass value="1.3431854176170634"/>
      <inertia ixx="0.002456" ixy="-0.0" ixz="-0.001302" iyy="0.003583" iyz="-0.0" izz="0.002394"/>
    </inertial>
    <visual>
      <origin rpy="0 0 0" xyz="-0.3385 -0.01 -0.140137"/>
      <geometry>
        <mesh filename="package://Spot_Arm_Export_description/meshes/link3_1.stl" scale="0.001 0.001 0.001"/>
      </geometry>
      <material name="silver"/>
    </visual>
    <collision>
      <origin rpy="0 0 0" xyz="-0.3385 -0.01 -0.140137"/>
      <geometry>
        <mesh filename="package://Spot_Arm_Export_description/meshes/link3_1.stl" scale="0.001 0.001 0.001"/>
      </geometry>
    </collision>
  </link>
  <link name="link4_1">
    <inertial>
      <origin rpy="0 0 0" xyz="0.09116530618238194 -4.470348317907382e-10 1.6517662931869737e-08"/>
      <mass value="1.9937738359972355"/>
      <inertia ixx="0.001271" ixy="-0.0" ixz="-0.0" iyy="0.006352" iyz="0.0" izz="0.006352"/>
    </inertial>
    <visual>
      <origin rpy="0 0 0" xyz="-0.4455 0.0 -0.237477"/>
      <geometry>
        <mesh filename="package://Spot_Arm_Export_description/meshes/link4_1.stl" scale="0.001 0.001 0.001"/>
      </geometry>
      <material name="silver"/>
    </visual>
    <collision>
      <origin rpy="0 0 0" xyz="-0.4455 0.0 -0.237477"/>
      <geometry>
        <mesh filename="package://Spot_Arm_Export_description/meshes/link4_1.stl" scale="0.001 0.001 0.001"/>
      </geometry>
    </collision>
  </link>
  <link name="link5_1">
    <inertial>
      <origin rpy="0 0 0" xyz="0.11485690332465609 -4.470348257432113e-10 1.6517662876358585e-08"/>
      <mass value="2.025824700134457"/>
      <inertia ixx="0.003336" ixy="-0.0" ixz="-0.0" iyy="0.010798" iyz="0.0" izz="0.010792"/>
    </inertial>
    <visual>
      <origin rpy="0 0 0" xyz="-0.4805 0.0 -0.237477"/>
      <geometry>
        <mesh filename="package://Spot_Arm_Export_description/meshes/link5_1.stl" scale="0.001 0.001 0.001"/>
      </geometry>
      <material name="yellow"/>
    </visual>
    <collision>
      <origin rpy="0 0 0" xyz="-0.4805 0.0 -0.237477"/>
      <geometry>
        <mesh filename="package://Spot_Arm_Export_description/meshes/link5_1.stl" scale="0.001 0.001 0.001"/>
      </geometry>
    </collision>
  </link>
  <link name="link6_1">
    <inertial>
      <origin rpy="0 0 0" xyz="0.05389380319242287 -0.010500000447034839 1.6516571749169984e-08"/>
      <mass value="1.0011757192825106"/>
      <inertia ixx="0.001219" ixy="0.0" ixz="-0.0" iyy="0.001201" iyz="-0.0" izz="0.001214"/>
    </inertial>
    <visual>
      <origin rpy="0 0 0" xyz="-0.7218 -0.01 -0.237477"/>
      <geometry>
        <mesh filename="package://Spot_Arm_Export_description/meshes/link6_1.stl" scale="0.001 0.001 0.001"/>
      </geometry>
      <material name="silver"/>
    </visual>
    <collision>
      <origin rpy="0 0 0" xyz="-0.7218 -0.01 -0.237477"/>
      <geometry>
        <mesh filename="package://Spot_Arm_Export_description/meshes/link6_1.stl" scale="0.001 0.001 0.001"/>
      </geometry>
    </collision>
  </link>
  <link name="link7_1">
    <inertial>
      <origin rpy="0 0 0" xyz="0.056163464375598826 9.814067565384844e-06 -0.010275722003246418"/>
      <mass value="1.6734994307062705"/>
      <inertia ixx="0.002751" ixy="-1e-06" ixz="0.000546" iyy="0.004068" iyz="0.0" izz="0.003961"/>
    </inertial>
    <visual>
      <origin rpy="0 0 0" xyz="-0.8218 0.0005 -0.237477"/>
      <geometry>
        <mesh filename="package://Spot_Arm_Export_description/meshes/link7_1.stl" scale="0.001 0.001 0.001"/>
      </geometry>
      <material name="black"/>
    </visual>
    <collision>
      <origin rpy="0 0 0" xyz="-0.8218 0.0005 -0.237477"/>
      <geometry>
        <mesh filename="package://Spot_Arm_Export_description/meshes/link7_1.stl" scale="0.001 0.001 0.001"/>
      </geometry>
    </collision>
  </link>
  <joint name="Rev7" type="revolute">
    <origin rpy="0 0 0" xyz="0.0 0.0 0.04"/>
    <parent link="base_link"/>
    <child link="link1_1"/>
    <axis xyz="0.0 0.0 1.0"/>
    <limit effort="500.0" lower="-2.61799" upper="3.14159" velocity="0.5"/>
  </joint>
  <joint name="Rev8" type="revolute">
    <origin rpy="0 0 0" xyz="0.0 0.03 0.1"/>
    <parent link="link1_1"/>
    <child link="link2__1"/>
    <axis xyz="0.0 -1.0 0.0"/>
    <limit effort="500.0" lower="-0.523599" upper="3.14159" velocity="0.5"/>
  </joint>
  <joint name="Rev9" type="revolute">
    <origin rpy="0 0 0" xyz="0.3385 -0.02 0.000137"/>
    <parent link="link2__1"/>
    <child link="link3_1"/>
    <axis xyz="0.0 1.0 0.0"/>
    <limit effort="500.0" lower="0" upper="2.61799" velocity="0.5"/>
  </joint>
  <joint name="Rev10" type="revolute">
    <origin rpy="0 0 0" xyz="0.107 -0.01 0.09734"/>
    <parent link="link3_1"/>
    <child link="link4_1"/>
    <limit effort="500.0" lower="-4.3633" upper="1.22173" velocity="0.5"/>
  </joint>
  <joint name="Slider11" type="prismatic">
    <origin rpy="0 0 0" xyz="0.035 0.0 0.0"/>
    <parent link="link4_1"/>
    <child link="link5_1"/>
    <axis xyz="1.0 -0.0 0.0"/>
    <limit effort="100" lower="0.0" upper="0.075" velocity="100"/>
  </joint>
  <joint name="Rev14" type="revolute">
    <origin rpy="0 0 0" xyz="0.2413 0.01 0.0"/>
    <parent link="link5_1"/>
    <child link="link6_1"/>
    <axis xyz="-0.0 1.0 0.0"/>
    <limit effort="500.0" lower="-1.047198" upper="1.047198" velocity="0.5"/>
  </joint>
  <joint name="Rev15" type="revolute">
    <origin rpy="0 0 0" xyz="0.1 -0.0105 0.0"/>
    <parent link="link6_1"/>
    <child link="link7_1"/>
    <axis xyz="-1.0 -0.0 -0.0"/>
    <limit effort="500.0" lower="-4.45059" upper="1.30899" velocity="0.5"/>
  </joint>
</robot>

